<?xml version="1.0"?>
<robot name="racecar" xmlns:xacro="http://www.ros.org/wiki/xacro">

  <xacro:include filename="$(find rover_description)/urdf/macros.xacro" />
  <xacro:include filename="$(find rover_description)/urdf/accessories/camera.urdf.xacro"/>
  <xacro:include filename="$(find ouster_description)/urdf/OS1-64.urdf.xacro"/>

  <!-- Add chassis and it's inertia link -->

  <link name="base_link" />

  <link name="chassis">
    <visual>
      <xacro:chassis_geometry/>
      <material name="blue" />
    </visual>
  </link>

  <joint name="base_link_joint" type="fixed">
    <origin xyz="0 0 0.05" rpy="0 0 0" />
    <parent link="base_link" />
    <child link="chassis" />
  </joint>

  <link name="chassis_inertia">
    <inertial>
      <xacro:chassis_inertial_params />
    </inertial>
  </link>

  <joint name="chassis_inertia_joint" type="fixed">
    <origin xyz="0 0 0" rpy="0 0 0" />
    <parent link="chassis" />
    <child link="chassis_inertia" />
  </joint>

  <!-- Add the left rear wheel with its joints and tranmissions -->

  <link name="left_rear_wheel">
    <inertial>
      <xacro:left_wheels_inertial_params />
    </inertial>
    <visual>
      <xacro:left_rear_wheel_geometry />
      <material name="black" />
    </visual>
    <collision>robot
      <xacro:left_wheels_collision_geometry />
    </collision>
  </link>

  <joint name="left_rear_wheel_joint" type="continuous">
    <origin xyz="0 0.1 0" rpy="1.5708 0 0" />
    <parent link="chassis" />
    <child link="left_rear_wheel" />
    <axis xyz="0 0 -1" />
    <limit effort="10" velocity="100" />
  </joint>

  <xacro:wheel_transmission name="left_rear_wheel" />

  <!-- Add the right rear wheel with its joints and tranmissions -->

  <link name="right_rear_wheel">
    <inertial>
      <xacro:right_wheels_inertial_params />
    </inertial>
    <visual>
      <xacro:right_rear_wheel_geometry />
      <material name="black" />
    </visual>
    <collision>
      <xacro:right_wheels_collision_geometry />
    </collision>
  </link>

  <joint name="right_rear_wheel_joint" type="continuous">
    <origin xyz="0 -0.1 0" rpy="1.5708 0 0" />
    <parent link="chassis" />
    <child link="right_rear_wheel" />
    <axis xyz="0 0 -1" />
    <limit effort="10" velocity="100" />
  </joint>

  <xacro:wheel_transmission name="right_rear_wheel" />

  <!-- Add the left steering hinge with its joints and tranmissions -->

  <link name="left_steering_hinge">
    <inertial>
      <xacro:steering_hinge_inertial_params />
    </inertial>
    <visual>
      <xacro:left_steering_hinge_geometry />
      <material name="grey" />
    </visual>
  </link>

  <joint name="left_steering_hinge_joint" type="revolute">
    <origin xyz="0.325 0.1 0" rpy="0 1.5708 0" />
    <parent link="chassis" />
    <child link="left_steering_hinge" />
    <axis xyz="-1 0 0" />
    <limit lower="-1.0" upper="1.0" effort="10" velocity="100" />
  </joint>

  <xacro:steering_hinge_transmission name="left_steering_hinge" />

  <!-- Add the right steering hinge with its joints and tranmissions -->

  <link name="right_steering_hinge">
    <inertial>
      <xacro:steering_hinge_inertial_params />
    </inertial>
    <visual>
      <xacro:right_steering_hinge_geometry />
      <material name="grey" />
    </visual>
  </link>

  <joint name="right_steering_hinge_joint" type="continuous">
    <origin xyz="0.325 -0.1 0" rpy="0 1.5708 0" />
    <parent link="chassis" />
    <child link="right_steering_hinge" />
    <axis xyz="-1 0 0" />
    <limit lower="-1.0" upper="1.0" effort="10" velocity="100" />
  </joint>

  <xacro:steering_hinge_transmission name="right_steering_hinge" />

  <!-- Add the left front wheel with its joints and tranmissions -->

  <link name="left_front_wheel">
    <inertial>
      <xacro:left_wheels_inertial_params />
    </inertial>
    <visual>
      <xacro:left_front_wheel_geometry />
      <material name="black" />
    </visual>
    <collision>
      <xacro:left_wheels_collision_geometry />
    </collision>
  </link>

  <joint name="left_front_wheel_joint" type="continuous">
    <origin xyz="0 0 0" rpy="1.5708 0 0" />
    <parent link="left_steering_hinge" />
    <child link="left_front_wheel" />
    <axis xyz="0 0 -1" />
    <limit effort="10" velocity="100" />
  </joint>

  <xacro:wheel_transmission name="left_front_wheel" />

  <!-- Add the left front wheel with its joints and tranmissions -->

  <link name="right_front_wheel">
    <inertial>
      <xacro:right_wheels_inertial_params />
    </inertial>
    <visual>
      <xacro:right_front_wheel_geometry />
      <material name="black" />
    </visual>
    <collision>
      <xacro:right_wheels_collision_geometry />
    </collision>
  </link>

  <joint name="right_front_wheel_joint" type="continuous">
    <origin xyz="0 0 0" rpy="1.5708 0 0" />
    <parent link="right_steering_hinge" />
    <child link="right_front_wheel" />
    <axis xyz="0 0 -1" />
    <limit effort="10" velocity="100"/>
  </joint>
  
  <xacro:wheel_transmission name="right_front_wheel" />

    <!-- Add a GPS link -->
    <link name="navsat_link"/>
    <joint name="navsat_joint" type="fixed">
      <parent link="chassis" />
      <child link="navsat_link" />
      <origin xyz="0.19 0 0.149" rpy="0 0 0" />
    </joint>
    <gazebo reference="navsat_link">
    </gazebo>
    
  

  <!--Mount a basic camera -->
    <xacro:camera_macro
      namespace="openmv_cam"
      parent_link="chassis"
      camera_suffix=""
      frame_rate="30"
      horizontal_fov="2"
      image_width="1280"
      image_height="720"
      image_format="R8G8B8"
      min_distance="0.02"
      max_distance="300"
      noise_mean="0.0"
      noise_stddev="0.007"
      enable_visual="true"
      >
      <box size="0.02 0.02 0.02" />
      <origin xyz="0.3 0.0 0.2" rpy="0 0 0" />
    </xacro:camera_macro>
     

  <!--Mount a OS1-64-->      
    <xacro:OS1-64
      parent="chassis"
      name="os1_sensor"
      hz="10"
      samples="220"
      min_range="0.1"
      >
      <origin xyz="0.2 0 0.3" rpy="0 0 0" />
    </xacro:OS1-64>
    

  <!-- Add Hokuyo laser scanner 

  <link name="laser">
    <inertial>
      <xacro:hokuyo_inertial_params />
    </inertial>
    <collision>
      <origin xyz="0 0 0" rpy="0 0 0"/>
      <geometry>
        <box size="0.1 0.1 0.1"/>
      </geometry>
    </collision>
    <visual>
      <origin xyz="0 0 0" rpy="0 0 0"/>
      <geometry>
        <mesh filename="package://rover_description/meshes/hokuyo.dae"/>
        <material name="grey" />
      </geometry>
    </visual>
  </link>

  <joint name="hokuyo_joint" type="fixed">
    <origin xyz="0.265 0.0 0.075" rpy="0 0 0"/>
    <parent link="chassis" />
    <child link="laser" />
    <axis xyz="0 0 1" />
  </joint>
-->


  <!-- zed camera 
  <link name="zed_camera_link">
    <inertial>
      <mass value="1e-5" />
      <origin xyz="0 0 0" rpy="0 0 0"/>
      <inertia ixx="1e-6" ixy="0" ixz="0" iyy="1e-6" iyz="0" izz="1e-6" />
    </inertial>
    <collision>
      <origin xyz="0 0 0" rpy="0 0 0"/>
      <geometry>
        <box size="0.033 0.175 0.030"/>
      </geometry>
    </collision>
    <visual>
      <origin xyz="0 0 0" rpy="0 0 0"/>
      <geometry>
        <box size="0.033 0.175 0.030"/>
      </geometry>
      <material name="red"/>
    </visual>
  </link>

  <joint name="zed_camera_joint" type="fixed">
    <origin xyz="0.390 0 0.04" rpy="0 0 0"/>
    <parent link="chassis"/>
    <child link="zed_camera_link"/>
    <axis xyz="0 0 1" />
  </joint>
-->


<!-- zed camera lenses -->
<!-- It seems these have to have a non-zero mass to have a camera attached? -->
<!-- this needs to match the name in zed_wrapper/zed_tf.launch -->
  <!--
  <link name="camera_link">
    <inertial>
      <mass value="1e-5" />
      <origin xyz="0 0 0" rpy="0 0 0"/>
      <inertia ixx="1e-6" ixy="0" ixz="0" iyy="1e-6" iyz="0" izz="1e-6" />
    </inertial>
  </link>
  <link name="zed_camera_right_link">
    <inertial>
      <mass value="1e-5" />
      <origin xyz="0 0 0" rpy="0 0 0"/>
      <inertia ixx="1e-6" ixy="0" ixz="0" iyy="1e-6" iyz="0" izz="1e-6" />
    </inertial>
  </link>

  <joint name="zed_camera_left_joint" type="fixed">
    <origin xyz="0 0.06 0" rpy="0 0 0"/>
    <parent link="zed_camera_link"/>
    <child link="camera_link"/>
    <axis xyz="0 0 1" />
  </joint>
  <joint name="zed_camera_right_joint" type="fixed">
    <origin xyz="0 -0.06 0" rpy="0 0 0"/>
    <parent link="zed_camera_link"/>
    <child link="zed_camera_right_link"/>
    <axis xyz="0 0 1" />
  </joint>
-->

<!-- Add the remaining xacros -->

<xacro:include filename="$(find rover_description)/urdf/racecar.gazebo" />
<xacro:include filename="$(find rover_description)/urdf/materials.xacro" />

</robot>
